2025-04-18 11:54:01,450 INFO    MainThread:3920306 [wandb_setup.py:_flush():67] Current SDK version is 0.19.9
2025-04-18 11:54:01,450 INFO    MainThread:3920306 [wandb_setup.py:_flush():67] Configure stats pid to 3920306
2025-04-18 11:54:01,450 INFO    MainThread:3920306 [wandb_setup.py:_flush():67] Loading settings from /home/jth264/.config/wandb/settings
2025-04-18 11:54:01,450 INFO    MainThread:3920306 [wandb_setup.py:_flush():67] Loading settings from /home/jth264/fish-benchmark/evaluation/wandb/settings
2025-04-18 11:54:01,450 INFO    MainThread:3920306 [wandb_setup.py:_flush():67] Loading settings from environment variables
2025-04-18 11:54:01,450 INFO    MainThread:3920306 [wandb_init.py:setup_run_log_directory():662] Logging user logs to /home/jth264/fish-benchmark/evaluation/wandb/run-20250418_115401-s390f4nk/logs/debug.log
2025-04-18 11:54:01,450 INFO    MainThread:3920306 [wandb_init.py:setup_run_log_directory():663] Logging internal logs to /home/jth264/fish-benchmark/evaluation/wandb/run-20250418_115401-s390f4nk/logs/debug-internal.log
2025-04-18 11:54:01,450 INFO    MainThread:3920306 [wandb_init.py:monkeypatch_ipython():581] configuring jupyter hooks <wandb.sdk.wandb_init._WandbInit object at 0x7ff1b1848a70>
2025-04-18 11:54:01,450 INFO    MainThread:3920306 [wandb_init.py:init():781] calling init triggers
2025-04-18 11:54:01,450 INFO    MainThread:3920306 [wandb_init.py:init():786] wandb.init called with sweep_config: {}
config: {'_wandb': {}}
2025-04-18 11:54:01,450 INFO    MainThread:3920306 [wandb_init.py:init():809] starting backend
2025-04-18 11:54:01,450 INFO    MainThread:3920306 [wandb_init.py:init():813] sending inform_init request
2025-04-18 11:54:01,453 INFO    MainThread:3920306 [backend.py:_multiprocessing_setup():101] multiprocessing start_methods=fork,spawn,forkserver, using: spawn
2025-04-18 11:54:01,453 INFO    MainThread:3920306 [wandb_init.py:init():823] backend started and connected
2025-04-18 11:54:01,454 INFO    MainThread:3920306 [wandb_run.py:_label_probe_notebook():1267] probe notebook
2025-04-18 11:54:01,456 INFO    MainThread:3920306 [wandb_init.py:init():915] updated telemetry
2025-04-18 11:54:01,461 INFO    MainThread:3920306 [wandb_init.py:init():939] communicating run to backend with 90.0 second timeout
2025-04-18 11:54:06,238 INFO    MainThread:3920306 [wandb_init.py:init():1014] starting run threads in backend
2025-04-18 11:54:06,385 INFO    MainThread:3920306 [wandb_run.py:_console_start():2454] atexit reg
2025-04-18 11:54:06,386 INFO    MainThread:3920306 [wandb_run.py:_redirect():2306] redirect: wrap_raw
2025-04-18 11:54:06,386 INFO    MainThread:3920306 [wandb_run.py:_redirect():2371] Wrapping output streams.
2025-04-18 11:54:06,386 INFO    MainThread:3920306 [wandb_run.py:_redirect():2394] Redirects installed.
2025-04-18 11:54:06,389 INFO    MainThread:3920306 [wandb_init.py:init():1056] run started, returning control to user process
2025-04-18 11:54:18,236 WARNING MsgRouterThr:3920306 [router.py:message_loop():63] [no run ID] message_loop has been closed
Traceback (most recent call last):
  File "/home/jth264/.conda/envs/benchmark/lib/python3.12/site-packages/wandb/sdk/interface/router_sock.py", line 27, in _read_message
    return self._sock_client.read_server_response(timeout=1)
           ^^^^^^^^^^^^^^^^^^^^^^^^^^^^^^^^^^^^^^^^^^^^^^^^^
  File "/home/jth264/.conda/envs/benchmark/lib/python3.12/site-packages/wandb/sdk/lib/sock_client.py", line 235, in read_server_response
    data = self._read_packet_bytes(timeout=timeout)
           ^^^^^^^^^^^^^^^^^^^^^^^^^^^^^^^^^^^^^^^^
  File "/home/jth264/.conda/envs/benchmark/lib/python3.12/site-packages/wandb/sdk/lib/sock_client.py", line 220, in _read_packet_bytes
    raise SockClientClosedError
wandb.sdk.lib.sock_client.SockClientClosedError

The above exception was the direct cause of the following exception:

Traceback (most recent call last):
  File "/home/jth264/.conda/envs/benchmark/lib/python3.12/site-packages/wandb/sdk/interface/router.py", line 56, in message_loop
    msg = self._read_message()
          ^^^^^^^^^^^^^^^^^^^^
  File "/home/jth264/.conda/envs/benchmark/lib/python3.12/site-packages/wandb/sdk/interface/router_sock.py", line 29, in _read_message
    raise MessageRouterClosedError from e
wandb.sdk.interface.router.MessageRouterClosedError
2025-04-18 11:54:18,287 INFO    MsgRouterThr:3920306 [mailbox.py:close():129] [no run ID] Closing mailbox, abandoning 1 handles.
2025-04-18 11:54:18,923 INFO    MainThread:3920306 [jupyter.py:save_ipynb():384] [no run ID] not saving jupyter notebook
2025-04-18 11:54:18,924 INFO    MainThread:3920306 [wandb_init.py:_pause_backend():546] [no run ID] pausing backend
2025-04-18 11:54:28,045 INFO    MainThread:3920306 [wandb_init.py:_resume_backend():551] [no run ID] resuming backend
2025-04-18 11:54:28,047 ERROR   MainThread:3920306 [redirect.py:_on_write():661] [no run ID] error in stdout callback
Traceback (most recent call last):
  File "/home/jth264/.conda/envs/benchmark/lib/python3.12/site-packages/IPython/core/events.py", line 82, in trigger
    func(*args, **kwargs)
  File "/home/jth264/.conda/envs/benchmark/lib/python3.12/site-packages/wandb/sdk/wandb_init.py", line 552, in _resume_backend
    self.backend.interface.publish_resume()
  File "/home/jth264/.conda/envs/benchmark/lib/python3.12/site-packages/wandb/sdk/interface/interface.py", line 777, in publish_resume
    self._publish_resume(resume)
  File "/home/jth264/.conda/envs/benchmark/lib/python3.12/site-packages/wandb/sdk/interface/interface_shared.py", line 293, in _publish_resume
    self._publish(rec)
  File "/home/jth264/.conda/envs/benchmark/lib/python3.12/site-packages/wandb/sdk/interface/interface_sock.py", line 39, in _publish
    self._sock_client.send_record_publish(record)
  File "/home/jth264/.conda/envs/benchmark/lib/python3.12/site-packages/wandb/sdk/lib/sock_client.py", line 174, in send_record_publish
    self.send_server_request(server_req)
  File "/home/jth264/.conda/envs/benchmark/lib/python3.12/site-packages/wandb/sdk/lib/sock_client.py", line 154, in send_server_request
    self._send_message(msg)
  File "/home/jth264/.conda/envs/benchmark/lib/python3.12/site-packages/wandb/sdk/lib/sock_client.py", line 151, in _send_message
    self._sendall_with_error_handle(header + data)
  File "/home/jth264/.conda/envs/benchmark/lib/python3.12/site-packages/wandb/sdk/lib/sock_client.py", line 130, in _sendall_with_error_handle
    sent = self._sock.send(data)
           ^^^^^^^^^^^^^^^^^^^^^
BrokenPipeError: [Errno 32] Broken pipe

During handling of the above exception, another exception occurred:

Traceback (most recent call last):
  File "/home/jth264/.conda/envs/benchmark/lib/python3.12/site-packages/wandb/sdk/lib/redirect.py", line 659, in _on_write
    cb(written_data)
  File "/home/jth264/.conda/envs/benchmark/lib/python3.12/site-packages/wandb/sdk/wandb_run.py", line 2375, in <lambda>
    lambda data: self._console_raw_callback("stdout", data),
                 ^^^^^^^^^^^^^^^^^^^^^^^^^^^^^^^^^^^^^^^^^^
  File "/home/jth264/.conda/envs/benchmark/lib/python3.12/site-packages/wandb/sdk/wandb_run.py", line 387, in wrapper
    return func(self, *args, **kwargs)
           ^^^^^^^^^^^^^^^^^^^^^^^^^^^
  File "/home/jth264/.conda/envs/benchmark/lib/python3.12/site-packages/wandb/sdk/wandb_run.py", line 435, in wrapper_fn
    return func(self, *args, **kwargs)
           ^^^^^^^^^^^^^^^^^^^^^^^^^^^
  File "/home/jth264/.conda/envs/benchmark/lib/python3.12/site-packages/wandb/sdk/wandb_run.py", line 1518, in _console_raw_callback
    self._backend.interface.publish_output_raw(name, data)
  File "/home/jth264/.conda/envs/benchmark/lib/python3.12/site-packages/wandb/sdk/interface/interface.py", line 761, in publish_output_raw
    self._publish_output_raw(o)
  File "/home/jth264/.conda/envs/benchmark/lib/python3.12/site-packages/wandb/sdk/interface/interface_shared.py", line 38, in _publish_output_raw
    self._publish(rec)
  File "/home/jth264/.conda/envs/benchmark/lib/python3.12/site-packages/wandb/sdk/interface/interface_sock.py", line 39, in _publish
    self._sock_client.send_record_publish(record)
  File "/home/jth264/.conda/envs/benchmark/lib/python3.12/site-packages/wandb/sdk/lib/sock_client.py", line 174, in send_record_publish
    self.send_server_request(server_req)
  File "/home/jth264/.conda/envs/benchmark/lib/python3.12/site-packages/wandb/sdk/lib/sock_client.py", line 154, in send_server_request
    self._send_message(msg)
  File "/home/jth264/.conda/envs/benchmark/lib/python3.12/site-packages/wandb/sdk/lib/sock_client.py", line 151, in _send_message
    self._sendall_with_error_handle(header + data)
  File "/home/jth264/.conda/envs/benchmark/lib/python3.12/site-packages/wandb/sdk/lib/sock_client.py", line 130, in _sendall_with_error_handle
    sent = self._sock.send(data)
           ^^^^^^^^^^^^^^^^^^^^^
BrokenPipeError: [Errno 32] Broken pipe
2025-04-18 11:54:28,131 ERROR   MainThread:3920306 [redirect.py:_on_write():661] [no run ID] error in stdout callback
Traceback (most recent call last):
  File "/home/jth264/.conda/envs/benchmark/lib/python3.12/site-packages/IPython/core/events.py", line 82, in trigger
    func(*args, **kwargs)
  File "/home/jth264/.conda/envs/benchmark/lib/python3.12/site-packages/wandb/sdk/wandb_init.py", line 552, in _resume_backend
    self.backend.interface.publish_resume()
  File "/home/jth264/.conda/envs/benchmark/lib/python3.12/site-packages/wandb/sdk/interface/interface.py", line 777, in publish_resume
    self._publish_resume(resume)
  File "/home/jth264/.conda/envs/benchmark/lib/python3.12/site-packages/wandb/sdk/interface/interface_shared.py", line 293, in _publish_resume
    self._publish(rec)
  File "/home/jth264/.conda/envs/benchmark/lib/python3.12/site-packages/wandb/sdk/interface/interface_sock.py", line 39, in _publish
    self._sock_client.send_record_publish(record)
  File "/home/jth264/.conda/envs/benchmark/lib/python3.12/site-packages/wandb/sdk/lib/sock_client.py", line 174, in send_record_publish
    self.send_server_request(server_req)
  File "/home/jth264/.conda/envs/benchmark/lib/python3.12/site-packages/wandb/sdk/lib/sock_client.py", line 154, in send_server_request
    self._send_message(msg)
  File "/home/jth264/.conda/envs/benchmark/lib/python3.12/site-packages/wandb/sdk/lib/sock_client.py", line 151, in _send_message
    self._sendall_with_error_handle(header + data)
  File "/home/jth264/.conda/envs/benchmark/lib/python3.12/site-packages/wandb/sdk/lib/sock_client.py", line 130, in _sendall_with_error_handle
    sent = self._sock.send(data)
           ^^^^^^^^^^^^^^^^^^^^^
BrokenPipeError: [Errno 32] Broken pipe

During handling of the above exception, another exception occurred:

Traceback (most recent call last):
  File "/home/jth264/.conda/envs/benchmark/lib/python3.12/site-packages/wandb/sdk/lib/redirect.py", line 659, in _on_write
    cb(written_data)
  File "/home/jth264/.conda/envs/benchmark/lib/python3.12/site-packages/wandb/sdk/wandb_run.py", line 2375, in <lambda>
    lambda data: self._console_raw_callback("stdout", data),
                 ^^^^^^^^^^^^^^^^^^^^^^^^^^^^^^^^^^^^^^^^^^
  File "/home/jth264/.conda/envs/benchmark/lib/python3.12/site-packages/wandb/sdk/wandb_run.py", line 387, in wrapper
    return func(self, *args, **kwargs)
           ^^^^^^^^^^^^^^^^^^^^^^^^^^^
  File "/home/jth264/.conda/envs/benchmark/lib/python3.12/site-packages/wandb/sdk/wandb_run.py", line 435, in wrapper_fn
    return func(self, *args, **kwargs)
           ^^^^^^^^^^^^^^^^^^^^^^^^^^^
  File "/home/jth264/.conda/envs/benchmark/lib/python3.12/site-packages/wandb/sdk/wandb_run.py", line 1518, in _console_raw_callback
    self._backend.interface.publish_output_raw(name, data)
  File "/home/jth264/.conda/envs/benchmark/lib/python3.12/site-packages/wandb/sdk/interface/interface.py", line 761, in publish_output_raw
    self._publish_output_raw(o)
  File "/home/jth264/.conda/envs/benchmark/lib/python3.12/site-packages/wandb/sdk/interface/interface_shared.py", line 38, in _publish_output_raw
    self._publish(rec)
  File "/home/jth264/.conda/envs/benchmark/lib/python3.12/site-packages/wandb/sdk/interface/interface_sock.py", line 39, in _publish
    self._sock_client.send_record_publish(record)
  File "/home/jth264/.conda/envs/benchmark/lib/python3.12/site-packages/wandb/sdk/lib/sock_client.py", line 174, in send_record_publish
    self.send_server_request(server_req)
  File "/home/jth264/.conda/envs/benchmark/lib/python3.12/site-packages/wandb/sdk/lib/sock_client.py", line 154, in send_server_request
    self._send_message(msg)
  File "/home/jth264/.conda/envs/benchmark/lib/python3.12/site-packages/wandb/sdk/lib/sock_client.py", line 151, in _send_message
    self._sendall_with_error_handle(header + data)
  File "/home/jth264/.conda/envs/benchmark/lib/python3.12/site-packages/wandb/sdk/lib/sock_client.py", line 130, in _sendall_with_error_handle
    sent = self._sock.send(data)
           ^^^^^^^^^^^^^^^^^^^^^
BrokenPipeError: [Errno 32] Broken pipe
2025-04-18 11:54:29,011 INFO    MainThread:3920306 [jupyter.py:save_ipynb():384] [no run ID] not saving jupyter notebook
2025-04-18 11:54:29,011 INFO    MainThread:3920306 [wandb_init.py:_pause_backend():546] [no run ID] pausing backend
2025-04-18 11:54:29,012 ERROR   MainThread:3920306 [redirect.py:_on_write():661] [no run ID] error in stdout callback
Traceback (most recent call last):
  File "/home/jth264/.conda/envs/benchmark/lib/python3.12/site-packages/IPython/core/events.py", line 82, in trigger
    func(*args, **kwargs)
  File "/home/jth264/.conda/envs/benchmark/lib/python3.12/site-packages/wandb/sdk/wandb_init.py", line 547, in _pause_backend
    self.backend.interface.publish_pause()
  File "/home/jth264/.conda/envs/benchmark/lib/python3.12/site-packages/wandb/sdk/interface/interface.py", line 769, in publish_pause
    self._publish_pause(pause)
  File "/home/jth264/.conda/envs/benchmark/lib/python3.12/site-packages/wandb/sdk/interface/interface_shared.py", line 289, in _publish_pause
    self._publish(rec)
  File "/home/jth264/.conda/envs/benchmark/lib/python3.12/site-packages/wandb/sdk/interface/interface_sock.py", line 39, in _publish
    self._sock_client.send_record_publish(record)
  File "/home/jth264/.conda/envs/benchmark/lib/python3.12/site-packages/wandb/sdk/lib/sock_client.py", line 174, in send_record_publish
    self.send_server_request(server_req)
  File "/home/jth264/.conda/envs/benchmark/lib/python3.12/site-packages/wandb/sdk/lib/sock_client.py", line 154, in send_server_request
    self._send_message(msg)
  File "/home/jth264/.conda/envs/benchmark/lib/python3.12/site-packages/wandb/sdk/lib/sock_client.py", line 151, in _send_message
    self._sendall_with_error_handle(header + data)
  File "/home/jth264/.conda/envs/benchmark/lib/python3.12/site-packages/wandb/sdk/lib/sock_client.py", line 130, in _sendall_with_error_handle
    sent = self._sock.send(data)
           ^^^^^^^^^^^^^^^^^^^^^
BrokenPipeError: [Errno 32] Broken pipe

During handling of the above exception, another exception occurred:

Traceback (most recent call last):
  File "/home/jth264/.conda/envs/benchmark/lib/python3.12/site-packages/wandb/sdk/lib/redirect.py", line 659, in _on_write
    cb(written_data)
  File "/home/jth264/.conda/envs/benchmark/lib/python3.12/site-packages/wandb/sdk/wandb_run.py", line 2375, in <lambda>
    lambda data: self._console_raw_callback("stdout", data),
                 ^^^^^^^^^^^^^^^^^^^^^^^^^^^^^^^^^^^^^^^^^^
  File "/home/jth264/.conda/envs/benchmark/lib/python3.12/site-packages/wandb/sdk/wandb_run.py", line 387, in wrapper
    return func(self, *args, **kwargs)
           ^^^^^^^^^^^^^^^^^^^^^^^^^^^
  File "/home/jth264/.conda/envs/benchmark/lib/python3.12/site-packages/wandb/sdk/wandb_run.py", line 435, in wrapper_fn
    return func(self, *args, **kwargs)
           ^^^^^^^^^^^^^^^^^^^^^^^^^^^
  File "/home/jth264/.conda/envs/benchmark/lib/python3.12/site-packages/wandb/sdk/wandb_run.py", line 1518, in _console_raw_callback
    self._backend.interface.publish_output_raw(name, data)
  File "/home/jth264/.conda/envs/benchmark/lib/python3.12/site-packages/wandb/sdk/interface/interface.py", line 761, in publish_output_raw
    self._publish_output_raw(o)
  File "/home/jth264/.conda/envs/benchmark/lib/python3.12/site-packages/wandb/sdk/interface/interface_shared.py", line 38, in _publish_output_raw
    self._publish(rec)
  File "/home/jth264/.conda/envs/benchmark/lib/python3.12/site-packages/wandb/sdk/interface/interface_sock.py", line 39, in _publish
    self._sock_client.send_record_publish(record)
  File "/home/jth264/.conda/envs/benchmark/lib/python3.12/site-packages/wandb/sdk/lib/sock_client.py", line 174, in send_record_publish
    self.send_server_request(server_req)
  File "/home/jth264/.conda/envs/benchmark/lib/python3.12/site-packages/wandb/sdk/lib/sock_client.py", line 154, in send_server_request
    self._send_message(msg)
  File "/home/jth264/.conda/envs/benchmark/lib/python3.12/site-packages/wandb/sdk/lib/sock_client.py", line 151, in _send_message
    self._sendall_with_error_handle(header + data)
  File "/home/jth264/.conda/envs/benchmark/lib/python3.12/site-packages/wandb/sdk/lib/sock_client.py", line 130, in _sendall_with_error_handle
    sent = self._sock.send(data)
           ^^^^^^^^^^^^^^^^^^^^^
BrokenPipeError: [Errno 32] Broken pipe
2025-04-18 11:54:29,013 ERROR   MainThread:3920306 [redirect.py:_on_write():661] [no run ID] error in stdout callback
Traceback (most recent call last):
  File "/home/jth264/.conda/envs/benchmark/lib/python3.12/site-packages/IPython/core/events.py", line 82, in trigger
    func(*args, **kwargs)
  File "/home/jth264/.conda/envs/benchmark/lib/python3.12/site-packages/wandb/sdk/wandb_init.py", line 547, in _pause_backend
    self.backend.interface.publish_pause()
  File "/home/jth264/.conda/envs/benchmark/lib/python3.12/site-packages/wandb/sdk/interface/interface.py", line 769, in publish_pause
    self._publish_pause(pause)
  File "/home/jth264/.conda/envs/benchmark/lib/python3.12/site-packages/wandb/sdk/interface/interface_shared.py", line 289, in _publish_pause
    self._publish(rec)
  File "/home/jth264/.conda/envs/benchmark/lib/python3.12/site-packages/wandb/sdk/interface/interface_sock.py", line 39, in _publish
    self._sock_client.send_record_publish(record)
  File "/home/jth264/.conda/envs/benchmark/lib/python3.12/site-packages/wandb/sdk/lib/sock_client.py", line 174, in send_record_publish
    self.send_server_request(server_req)
  File "/home/jth264/.conda/envs/benchmark/lib/python3.12/site-packages/wandb/sdk/lib/sock_client.py", line 154, in send_server_request
    self._send_message(msg)
  File "/home/jth264/.conda/envs/benchmark/lib/python3.12/site-packages/wandb/sdk/lib/sock_client.py", line 151, in _send_message
    self._sendall_with_error_handle(header + data)
  File "/home/jth264/.conda/envs/benchmark/lib/python3.12/site-packages/wandb/sdk/lib/sock_client.py", line 130, in _sendall_with_error_handle
    sent = self._sock.send(data)
           ^^^^^^^^^^^^^^^^^^^^^
BrokenPipeError: [Errno 32] Broken pipe

During handling of the above exception, another exception occurred:

Traceback (most recent call last):
  File "/home/jth264/.conda/envs/benchmark/lib/python3.12/site-packages/wandb/sdk/lib/redirect.py", line 659, in _on_write
    cb(written_data)
  File "/home/jth264/.conda/envs/benchmark/lib/python3.12/site-packages/wandb/sdk/wandb_run.py", line 2375, in <lambda>
    lambda data: self._console_raw_callback("stdout", data),
                 ^^^^^^^^^^^^^^^^^^^^^^^^^^^^^^^^^^^^^^^^^^
  File "/home/jth264/.conda/envs/benchmark/lib/python3.12/site-packages/wandb/sdk/wandb_run.py", line 387, in wrapper
    return func(self, *args, **kwargs)
           ^^^^^^^^^^^^^^^^^^^^^^^^^^^
  File "/home/jth264/.conda/envs/benchmark/lib/python3.12/site-packages/wandb/sdk/wandb_run.py", line 435, in wrapper_fn
    return func(self, *args, **kwargs)
           ^^^^^^^^^^^^^^^^^^^^^^^^^^^
  File "/home/jth264/.conda/envs/benchmark/lib/python3.12/site-packages/wandb/sdk/wandb_run.py", line 1518, in _console_raw_callback
    self._backend.interface.publish_output_raw(name, data)
  File "/home/jth264/.conda/envs/benchmark/lib/python3.12/site-packages/wandb/sdk/interface/interface.py", line 761, in publish_output_raw
    self._publish_output_raw(o)
  File "/home/jth264/.conda/envs/benchmark/lib/python3.12/site-packages/wandb/sdk/interface/interface_shared.py", line 38, in _publish_output_raw
    self._publish(rec)
  File "/home/jth264/.conda/envs/benchmark/lib/python3.12/site-packages/wandb/sdk/interface/interface_sock.py", line 39, in _publish
    self._sock_client.send_record_publish(record)
  File "/home/jth264/.conda/envs/benchmark/lib/python3.12/site-packages/wandb/sdk/lib/sock_client.py", line 174, in send_record_publish
    self.send_server_request(server_req)
  File "/home/jth264/.conda/envs/benchmark/lib/python3.12/site-packages/wandb/sdk/lib/sock_client.py", line 154, in send_server_request
    self._send_message(msg)
  File "/home/jth264/.conda/envs/benchmark/lib/python3.12/site-packages/wandb/sdk/lib/sock_client.py", line 151, in _send_message
    self._sendall_with_error_handle(header + data)
  File "/home/jth264/.conda/envs/benchmark/lib/python3.12/site-packages/wandb/sdk/lib/sock_client.py", line 130, in _sendall_with_error_handle
    sent = self._sock.send(data)
           ^^^^^^^^^^^^^^^^^^^^^
BrokenPipeError: [Errno 32] Broken pipe
